Workbook

Sheet Read Me
A1: TrustHome PH — Use Cases & Test Cases Catalog (Rev 2, 2026-10-01)
A2: Built from the Rev 2 document set (01–07 PDFs) and the Current Progress Report (Oct 1, 2026). Earlier sources (Build Instructions, System Build Plan, Firebase Setup Plan, Design Guide, Versioning Plan) are superseded; see the mapping below.
A4: Sheets
A5: Use Cases — 48 use cases (UC-43 to UC-48 added in Rev 2).
A6: Test Cases — 202 test cases. IDs from the QA doc are kept; new ones continue each prefix. Rev 2 adds TC-PURP, TC-API, TC-DOC, TC-OPS and TC-NOTIF-012 to 015.
A7: Summary — live counts by module, status and origin (formulas; update automatically). "Unassigned module check" must be 0.
A8: Proposed FRs — FR-019 to FR-029 and NFR-COST-01, NFR-SEC-02, NFR-REL-02 for the QA doc.
A10: What changed in Rev 2 (Oct 1)
A11: 1. Rules were deployed on Oct 1 (commit a1fe48e), so 23 cases that waited on "BUG-008 / rules deploy" moved from Blocked to Not Run. Run them now.
A12: 2. Cases that need live booking confirmation stay Blocked by F-05 until the trusted API (v1.4) is deployed: TC-SEC-002, TC-NOTIF-002.
A13: 3. Cases that need private documents stay Blocked by F-16 until v1.4: TC-VER-006, document part of TC-SEC-003.
A14: 4. TC-MAP-003 changed Failed -> Passed (Sep 30 live test). TC-SEC-007 changed Not Run -> Passed (rules deployed).
... A40: QA Documentation (test approach) -> 07 QA & Testing Strategy

Sheet Use Cases
A1: UC ID | B1: Use Case | C1: Module | D1: Primary Actor | E1: Related FR | F1: Preconditions | G1: Main Flow | H1: Alternate / Exception Flows | I1: Postconditions | J1: Source | K1: Version
A2: UC-01 | B2: Register an account | C2: Authentication | D2: Guest | E2: FR-001 | F2: Visitor is signed out. | G2: 1. Open Login / Register. 2. Enter name, email, password. 3. Submit. 4. System creates Firebase Auth account and users/{uid} profile (role user, status active). 5. Redirect to home/dashboard. | H2: A1. Email already in use -> inline error. A2. Weak/short password -> inline error. A3. Network failure -> error message, no partial profile. | I2: User is signed in with an active user profile. | J2: Build Instructions §2.3, §6; Firebase Setup §4 | K2: v0.1
A3: UC-02 | B3: Log in with email and password | C3: Authentication | D3: User / Admin | E3: FR-001 | F3: Account exists. | G3: 1. Open Login. 2. Enter email + password. 3. System authenticates and loads profile. 4. Redirect to the user's landing page. | H3: A1. Wrong password / unknown email -> inline error, no session. A2. Suspended account -> suspended-account screen; protected actions blocked. | I3: Session active; nav shows account menu + bell. | J3: Build Instructions §6 | K3: v0.1
A4: UC-03 | B4: Sign in with Google | C4: Authentication | D4: Guest / User | E4: FR-001 | F4: Google sign-in enabled in Firebase. | G4: 1. Click Continue with Google. 2. Choose account. 3. On first sign-in, system creates users profile. 4. Redirect. | H4: A1. User closes popup -> stays on login, no error loop. A2. Existing email/password account with same email -> handled without duplicate profile. | I4: Signed in; single profile per UID. | J4: Firebase Setup §4 | K4: v0.1
A5: UC-04 | B5: Log out | C5: Authentication | D5: User / Admin | E5: FR-001 | F5: User is signed in. | G5: 1. Open account menu. 2. Click Log out. 3. Session cleared; redirected to public page. | H5: A1. Using back button after logout does not reveal protected pages. | I5: Signed out. | J5: Design Guide p.10 | K5: v0.1
A6: UC-05 | B6: Manage profile / account | C6: Account | D6: User | E6: FR-001 | F6: Signed in. | G6: 1. Open profile/account page. 2. Edit allowed fields (e.g., name). 3. Save. | H6: A1. User cannot change own role or status (rules deny). | I6: Profile updated; role/status unchanged. | J6: Progress Report v0.1 | K6: v0.1
A7: UC-06 | B7: Create a listing and submit for review | C7: Listing Intake | D7: User (Owner) | E7: FR-002, FR-003 | F7: Signed in, active account. | G7: 1. Open Create Listing (multi-step). 2. Enter type, address/area, city, bedrooms, bathrooms, size, rent, availability date, amenities, description. 3. Upload >= 4 photos to Cloudinary. 4. Upload one ownership document + one government photo ID. 5. Add >= 1 showing window (day + start/end time). 6. Optionally place an approximate map pin. 7. Submit -> verificationStatus = pending. | H7: A1. Missing required field -> field-level error, submission blocked. A2. Description empty/whitespace or > 400 words -> blocked (150 words is a recommendation only). A3. < 4 photos -> blocked. A4. Missing either document -> blocked. A5. No valid showing window / end before start -> blocked. A6. Upload fails -> error, user can retry. | I7: Pending listing (not public); exact address stored in listingPrivate/{id}; public doc has no address field. | J7: Build Instructions §2.1–2.3; Progress Report v1.1, P1 | K7: v0.1 / v1.1
A8: UC-07 | B8: Edit a listing / resubmit after changes requested | C8: Listing Intake | D8: User (Owner) | E8: FR-002, FR-003 | F8: Owner has an existing listing. | G8: 1. Open My Listings -> Edit. 2. Change fields/photos/documents/showing windows. 3. Save / resubmit. 4. If status was changes-requested, listing returns to pending. | H8: A1. Edit breaks any intake rule -> same errors as creation (edit parity). A2. Non-owner opens edit URL -> denied. | I8: Listing updated; resubmitted listing back in admin queue. | J8: Progress Report v1.1 | K8: v1.1
A9: UC-08 | B9: Set location with approximate map pin | C9: Listing Map & Privacy | D9: User (Owner) | E9: FR-022 | F9: Owner on create/edit listing. | G9: 1. Type a location in map search. 2. Geocoder (with PH-specific retry) returns a pin. 3. Or click 'Use my exact address' to geocode the private address. 4. Adjust pin; save. 5. Public doc stores only a 5-char geohash marked approximate. | H9: A1. Address not found -> message; owner can place pin manually. A2. Invalid coordinates -> rejected. A3. Pin optional -> listing saves without map. A4. OPEN BUG: 'Use my exact address' button not rendering in live browser. | I9: Public listing has coarse location only; exact lat/long never public. | J9: Progress Report P2 Map; cleanup 2026-09-30 | K9: v1.3+
A10: UC-09 | B10: View My Listings | C10: Owner Listing Visibility | D10: User (Owner) | E10: FR-023 | F10: Signed in; owns >= 0 listings. | G10: 1. Open My Activity -> My Listings. 2. See card per listing: photo, city, type, bedrooms, price, verification status, review note, pending-request count. 3. View / Edit actions. 4. Tap request count -> Booking Requests tab filtered to that listing. | H10: A1. No listings -> empty state with Create Listing CTA. A2. Request count fails to load -> 'unavailable' state (not zero). | I10: Owner sees status of every listing; exact address/documents not shown. | J10: Progress Report P1 Owner visibility | K10: v1.3+
A11: UC-10 | B11: Review a pending listing | C11: Admin Listing Review | D11: Admin | E11: FR-003 | F11: Admin signed in; pending listing exists. | G11: 1. Open Listing Review Queue. 2. View photos; ownership document and government ID load through short-lived URLs from GET /api/listings/{id}/documents/{kind}. 3. Check name match + document validity (plausibility only). 4. Choose Approve, Request changes (with note), or Reject (with note). 5. Owner is notified. | H11: A1. Document PDF fails to render -> link still openable. A2. Queue load fails -> error + Retry. | I11: Approved -> verified + verifiedAt, public with 'Verified – document reviewed' badge. Changes requested -> owner sees note. Rejected -> permanent. | J11: Build Instructions §2.2, §2.3; Build Plan §3 | K11: v0.1 / v1.1
A12: UC-11 | B12: Browse and filter verified listings | C12: Search & Browse | D12: Guest / User | E12: FR-004 | F12: Verified listings exist. | G12: 1. Open Browse. 2. Apply city, price range, type filters. 3. Results sorted by Trust & Fairness Score by default. 4. Change sort. | H12: A1. No matches -> empty state. A2. Pending/rejected/suspended listings never shown. | I12: Filtered verified list displayed. | J12: Build Instructions §3.1; Design Guide p.2 | K12: v0.1
... A49: UC-48 | B49: Migrate verification documents to private delivery | C49: Private Documents | D49: Team lead | E49: FR-028 | F49: Backup taken; API deployed. | G49: 1. Run migration in dry-run mode and review counts. 2. Apply: change each legacy asset to authenticated type, store publicId in listingPrivate, remove URL fields from listings. 3. Spot-check old URLs no longer load. | H49: A1. Asset missing in Cloudinary -> report row for manual follow-up. | I49: No verification document is reachable from a public URL. | J49: Security & Privacy §5 | K49: v1.4

Sheet Test Cases
A1: TC ID | B1: UC ID | C1: FR ID | D1: Module | E1: Title | F1: Test Type | G1: Priority | H1: Preconditions | I1: Test Steps | J1: Test Data | K1: Expected Result | L1: Origin | M1: Status | N1: Actual Result | O1: Tester | P1: Date | Q1: Remarks
A2: TC-AUTH-001 | B2: UC-01 | C2: FR-001 | D2: Authentication | E2: Register with valid email/password | F2: Functional | G2: High | H2: Signed out | I2: 1. Open Register. 2. Enter name, email, password. 3. Submit. | J2: New email; password >= 6 chars | K2: Account created; users/{uid} saved with role user, status active; redirected. | L2: Existing (QA doc) | M2: Passed (Dev) | Q2: Re-run on deployed build.
A3: TC-AUTH-002 | B3: UC-02 | C3: FR-001 | D3: Authentication | E3: Login with wrong password | F3: Negative | G3: High | H3: Registered account | I3: 1. Open Login. 2. Enter registered email + wrong password. 3. Submit. | J3: Registered test account | K3: Inline error shown; no session created. | L3: Existing (QA doc) | M3: Passed (Dev)
A4: TC-AUTH-003 | B4: UC-03 | C4: FR-001 | D4: Authentication | E4: Google sign-in creates profile on first login | F4: Functional | G4: High | H4: Google sign-in enabled | I4: 1. Click Continue with Google. 2. Pick account. | J4: Google test account | K4: Signed in; profile created on first sign-in only. | L4: Existing (QA doc) | M4: Passed (Dev)
A5: TC-AUTH-004 | B5: UC-01 | C5: FR-001 | D5: Authentication | E5: Register with an email already in use | F5: Negative | G5: Medium | H5: Account exists | I5: 1. Register again with same email. | J5: Existing email | K5: Inline 'email already in use' error; no second profile. | L5: New | M5: Not Run
A6: TC-AUTH-005 | B6: UC-01 | C6: FR-001 | D6: Authentication | E6: Register with weak password / invalid email | F6: Negative | G6: Medium | H6: Signed out | I6: 1. Enter 'abc' as password, or 'user@' as email. 2. Submit. | J6: Invalid inputs | K6: Inline field errors; submit blocked. | L6: New | M6: Not Run
A7: TC-AUTH-006 | B7: UC-02 | C7: FR-001 | D7: Authentication | E7: Login with valid credentials | F7: Functional | G7: High | H7: Registered account | I7: 1. Enter valid email + password. 2. Submit. | J7: Registered account | K7: Signed in; account menu + bell visible; redirected. | L7: New | M7: Not Run | Q7: Mirrors acceptance criteria US-001.
A8: TC-AUTH-007 | B8: UC-02 | C8: FR-016 | D8: Authentication | E8: Suspended account login | F8: Negative | G8: High | H8: Account suspended by admin | I8: 1. Log in as suspended user. 2. Try to create listing / book. | J8: Suspended test user | K8: Suspended-account screen/notice; protected actions blocked by UI and rules. | L8: New | M8: Not Run
A9: TC-AUTH-008 | B9: UC-04 | C9: FR-001 | D9: Authentication | E9: Logout clears session | F9: Functional | G9: Medium | H9: Signed in | I9: 1. Log out. 2. Press browser Back. 3. Open /notifications directly. | J9: Any user | K9: Session cleared; protected pages redirect to login. | L9: New | M9: Not Run
A10: TC-AUTH-009 | B10: UC-03 | C10: FR-001 | D10: Authentication | E10: Cancel Google popup | F10: Negative | G10: Low | H10: Signed out | I10: 1. Click Continue with Google. 2. Close popup. | J10: - | K10: Stays on login with no crash or infinite spinner. | L10: New | M10: Not Run
A11: TC-AUTH-010 | B11: UC-05 | C11: FR-001 | D11: Authentication | E11: User cannot escalate own role/status | F11: Security | G11: High | H11: Signed in as regular user | I11: 1. Via SDK/console, update own users doc role='admin' or status='active' while suspended. | J11: Regular user | K11: Write denied by Firestore rules. | L11: New | M11: Not Run | Q11: Unblocked 2026-10-01: rules deployed to trusthome-ph (commit a1fe48e). Run on the live test project.
A12: TC-LIST-001 | B12: UC-06 | C12: FR-002 | D12: Listing Intake | E12: Submit a complete valid listing | F12: Functional | G12: High | H12: Signed in | I12: 1. Complete Create Listing. 2. Upload >=4 photos + both documents. 3. Add showing window. 4. Submit. | J12: Valid listing data | K12: Listing saved as pending; not in public search; appears in admin queue. | L12: Existing (QA doc) | M12: Passed (Dev) | Q12: Intake rules extended in v1.1.
A13: TC-INTAKE-001 | B13: UC-06 | C13: FR-002 | D13: Listing Intake | E13: Description length rules (updated) | F13: Negative/Boundary | G13: High | H13: Otherwise valid listing | I13: 1. Submit with empty/whitespace description. 2. Submit with 120 words. 3. Submit with 410 words. | J13: Descriptions: blank, 120 words, 410 words | K13: Blank -> blocked. 120 words -> ACCEPTED (150 is a recommendation hint only). 410 words -> blocked with inline guidance. | L13: Updated | M13: Not Run | Q13: Expected result changed by P1 description fix (was: 120 words blocked). Update QA doc Table 4 & FR-002.
A14: TC-INTAKE-001B | B14: UC-06 | C14: FR-002 | D14: Listing Intake | E14: Description boundaries 1 / 400 / 401 words | F14: Boundary | G14: Medium | H14: Otherwise valid listing | I14: 1. Submit 1-word, 400-word, 401-word descriptions. | J14: Generated text | K14: 1 and 400 accepted; 401 blocked. | L14: New | M14: Not Run
A15: TC-INTAKE-002 | B15: UC-06 | C15: FR-002 | D15: Listing Intake | E15: Fewer than 4 photos | F15: Negative | G15: High | H15: Otherwise valid listing | I15: 1. Upload 3 photos. 2. Submit. | J15: 3 images | K15: Blocked: minimum 4 photos. | L15: Existing (QA doc) | M15: Passed (Dev) | Q15: Unit test.
A16: TC-INTAKE-003 | B16: UC-06 | C16: FR-003 | D16: Listing Intake | E16: Missing government ID or ownership document | F16: Negative | G16: High | H16: Otherwise valid listing | I16: 1. Upload only ownership doc; submit. 2. Upload only gov ID; submit. | J16: One document each | K16: Both blocked until both documents are uploaded. | L16: Existing (QA doc) | M16: Passed (Dev)
A17: TC-INTAKE-004 | B17: UC-06 | C17: FR-002 | D17: Listing Intake | E17: Invalid or missing showing window | F17: Negative | G17: High | H17: Otherwise valid listing | I17: 1. Remove all windows. 2. Enter end time before start time. | J17: Window 14:00–10:00 | K17: Blocked: at least one valid window required. | L17: Existing (QA doc) | M17: Passed (Dev)
A18: TC-INTAKE-005 | B18: UC-07 | C18: FR-003 | D18: Listing Intake | E18: Request changes then resubmit | F18: Functional | G18: High | H18: Pending listing | I18: 1. Admin selects Request changes with note. 2. Owner opens My Listings, sees note. 3. Edits and resubmits. | J18: Pending listing | K18: Owner sees changes-requested + note; resubmission returns listing to pending. | L18: Existing (QA doc) | M18: Passed (Dev)
A19: TC-INTAKE-006 | B19: UC-07 | C19: FR-002 | D19: Listing Intake | E19: Edit parity with creation rules | F19: Negative | G19: High | H19: Existing listing | I19: 1. Edit listing; reduce to 2 photos / blank description. 2. Save. | J19: Existing listing | K19: Same validation errors as creation; not saved. | L19: Existing (QA doc) | M19: Passed (Dev)
A20: TC-INTAKE-007 | B20: UC-06 | C20: FR-002 | D20: Listing Intake | E20: Each required field missing | F20: Negative | G20: High | H20: Create Listing form | I20: 1. For each of type, address/area, city, bedrooms, bathrooms, size, rent, availability date, amenities: leave blank and submit. | J20: Otherwise valid listing | K20: Field-level inline error under the missing field; no listing doc created. | L20: New | M20: Not Run | Q20: Data-driven: 9 iterations.
A21: TC-INTAKE-008 | B21: UC-06 | C21: FR-002 | D21: Listing Intake | E21: Numeric field validation | F21: Negative/Boundary | G21: Medium | H21: Create Listing form | I21: 1. Enter 0 / negative / non-numeric for rent, size, bedrooms, bathrooms. | J21: -1, 0, 'abc' | K21: Rejected with inline error. | L21: New | M21: Not Run
A22: TC-INTAKE-009 | B22: UC-06 | C22: FR-002 | D22: Listing Intake | E22: Non-image or oversized photo upload | F22: Negative | G22: Medium | H22: Create Listing form | I22: 1. Upload a .exe/.txt as photo. 2. Upload very large image. | J22: Invalid files | K22: Rejected with clear message; no broken URL saved. | L22: New | M22: Not Run
A23: TC-INTAKE-010 | B23: UC-06 | C23: FR-003 | D23: Listing Intake | E23: Upload failure feedback | F23: Negative | G23: Medium | H23: Create Listing form | I23: 1. Go offline during photo/document upload. | J23: DevTools offline | K23: Error shown with retry; submit stays blocked until upload succeeds. | L23: New | M23: Not Run | Q23: Design Guide B8 feedback rule.
A24: TC-INTAKE-011 | B24: UC-06 | C24: FR-002 | D24: Listing Intake | E24: Multi-step form progress indicator | F24: UI | G24: Low | H24: Create Listing form | I24: 1. Walk through details -> photos -> documents steps. | J24: - | K24: Progress indicator shown; data kept when moving back/forward. | L24: New | M24: Not Run | Q24: Design Guide B8.
A25: TC-INTAKE-012 | B25: UC-06 | C25: FR-003 | D25: Listing Intake | E25: Limitation copy shown | F25: UI | G25: Medium | H25: Create Listing / Listing Detail | I25: 1. Read verification copy. | J25: - | K25: UI states review is a document-plausibility check, not a legal title search. | L25: New | M25: Not Run | Q25: Build Instructions §7.
A26: TC-INTAKE-013 | B26: UC-07 | C26: FR-002 | D26: Listing Intake | E26: Non-owner cannot edit listing | F26: Security | G26: High | H26: Listing owned by user A | I26: 1. As user B open /listings/{id}/edit. 2. Attempt direct update. | J26: Two users | K26: UI denies; Firestore update denied. | L26: New | M26: Not Run | Q26: Unblocked 2026-10-01: rules deployed to trusthome-ph (commit a1fe48e). Run on the live test project.
A27: TC-VER-001 | B27: UC-10 | C27: FR-003 | D27: Admin Listing Review | E27: Approve a pending listing | F27: Functional | G27: High | H27: Admin; pending listing | I27: 1. Open Listing Review Queue. 2. Approve. | J27: Seeded pending listing | K27: verified + verifiedAt; appears in search with 'Verified – document reviewed' badge; owner notified. | L27: Existing (QA doc) | M27: Passed (Dev) | Q27: Photo/PDF rendering fixed (BUG-002).
A28: TC-VER-002 | B28: UC-41 | C28: FR-003 | D28: Admin Listing Review | E28: Signed-out read of pending listing | F28: Security | G28: High | H28: Pending listing | I28: 1. Sign out. 2. Read pending listing by ID. | J28: Pending listing ID | K28: Read denied. | L28: Existing (QA doc) | M28: Not Run | Q28: Unblocked 2026-10-01: rules deployed to trusthome-ph (commit a1fe48e). Run on the live test project.
A29: TC-VER-003 | B29: UC-10 | C29: FR-003 | D29: Admin Listing Review | E29: Reject a listing with note | F29: Functional | G29: High | H29: Admin; pending listing | I29: 1. Reject with reason. | J29: Pending listing | K29: Status rejected; owner sees reason and is notified; never public. | L29: New | M29: Not Run
A30: TC-VER-004 | B30: UC-10 | C30: FR-003 | D30: Admin Listing Review | E30: Queue shows both documents + account name | F30: Functional | G30: High | H30: Pending listing with photo + PDF docs | I30: 1. Open item in queue. | J30: JPG ID + PDF deed | K30: Photos, ownership doc and gov ID viewable next to account name. | L30: New | M30: Not Run | Q30: Regression for BUG-002; depends on BUG-006.
A31: TC-VER-005 | B31: UC-10 | C31: FR-003 | D31: Admin Listing Review | E31: Non-admin cannot approve | F31: Security | G31: High | H31: Regular user | I31: 1. Direct write verificationStatus='verified' on own listing. | J31: Own pending listing | K31: Write denied. | L31: New | M31: Not Run | Q31: Unblocked 2026-10-01: rules deployed to trusthome-ph (commit a1fe48e). Run on the live test project.
A32: TC-VER-006 | B32: UC-10 | C32: FR-003 | D32: Admin Listing Review | E32: Documents not exposed publicly | F32: Security | G32: High | H32: Verified listing | I32: 1. As guest, open listing detail and inspect network/page source. | J32: Verified listing | K32: No ownership/ID document URLs in public data. | L32: New | M32: Blocked | Q32: Blocked by F-16: needs private documents + migration (v1.4). See TC-DOC-001 to 009.
A33: TC-VER-007 | B33: UC-10 | C33: FR-003 | D33: Admin Listing Review | E33: Empty review queue state | F33: UI | G33: Low | H33: No pending listings | I33: 1. Open queue. | J33: - | K33: Empty-state message, no error. | L33: New | M33: Not Run
A34: TC-SRCH-001 | B34: UC-11 | C34: FR-004 | D34: Search & Browse | E34: Filter by city, price, type | F34: Functional | G34: High | H34: Seeded listings | I34: 1. Open Browse. 2. Apply filters. | J34: Several cities | K34: Only verified matches shown; empty state when none. | L34: Existing (QA doc) | M34: Passed (Dev)
A35: TC-SRCH-002 | B35: UC-11 | C35: FR-010 | D35: Search & Browse | E35: Default sort by trust score | F35: Integration | G35: High | H35: Workflow run | I35: 1. Run workflow. 2. Check computedAt. 3. Open Browse. | J35: Seeded bookings/ratings | K35: Listings ordered by score, differing from price/recency sort. | L35: Existing (QA doc) | M35: Passed (Dev)
A36: TC-SRCH-003 | B36: UC-11 | C36: FR-004 | D36: Search & Browse | E36: Pending/rejected/suspended listings excluded | F36: Functional | G36: High | H36: Mixed statuses seeded | I36: 1. Browse without filters. | J36: Mixed listings | K36: Only verified, non-suspended listings shown. | L36: New | M36: Not Run
A37: TC-SRCH-004 | B37: UC-11 | C37: FR-004 | D37: Search & Browse | E37: Price range boundaries | F37: Boundary | G37: Medium | H37: Seeded listings | I37: 1. Set min=max=exact price of one listing. 2. Set min > max. | J37: Known prices | K37: Inclusive match; invalid range handled with message. | L37: New | M37: Not Run
A38: TC-SRCH-005 | B38: UC-12 | C38: FR-004 | D38: Search & Browse | E38: Listing detail content above the fold | F38: UI | G38: Medium | H38: Verified listing | I38: 1. Open listing at 390 px. | J38: - | K38: Verified badge + trust score visible without scrolling; Request Booking is the dominant CTA. | L38: New | M38: Not Run | Q38: Design Guide Part C.
A39: TC-SRCH-006 | B39: UC-12 | C39: FR-001 | D39: Search & Browse | E39: Guest clicks Request Booking | F39: Functional | G39: Medium | H39: Signed out | I39: 1. Open listing. 2. Click Request Booking. | J39: - | K39: Prompted to sign in; returns to listing after login. | L39: New | M39: Not Run
A40: TC-SRCH-007 | B40: UC-12 | C40: FR-004 | D40: Search & Browse | E40: Home shows live verified listings only | F40: Functional | G40: Low | H40: - | I40: 1. Open Home. | J40: - | K40: Rental showcase uses verified live listings; no sample cards. | L40: New | M40: Not Run | Q40: P2 navigation change.
...

Sheet Summary
A1: Test Cases by Module and Status
A2: Module | B2: Total | C2: Passed | D2: Passed (Dev) | E2: Failed | F2: Blocked | G2: Not Run | H2: Retired | I2: Executed | J2: Pass Rate
A3: Authentication | B3: =COUNTIF('Test Cases'!$D$2:$D$203,A3) | C3: =COUNTIFS('Test Cases'!$D$2:$D$203,$A3,'Test Cases'!$M$2:$M$203,"Passed") | D3: =COUNTIFS('Test Cases'!$D$2:$D$203,$A3,'Test Cases'!$M$2:$M$203,"Passed (Dev)") | E3: =COUNTIFS('Test Cases'!$D$2:$D$203,$A3,'Test Cases'!$M$2:$M$203,"Failed") | F3: =COUNTIFS('Test Cases'!$D$2:$D$203,$A3,'Test Cases'!$M$2:$M$203,"Blocked") | G3: =COUNTIFS('Test Cases'!$D$2:$D$203,$A3,'Test Cases'!$M$2:$M$203,"Not Run") | H3: =COUNTIFS('Test Cases'!$D$2:$D$203,$A3,'Test Cases'!$M$2:$M$203,"Retired") | I3: =C3+D3+E3 | J3: =IF(I3=0,"-",(C3+D3)/I3)
A4: Listing Intake | B4: =COUNTIF('Test Cases'!$D$2:$D$203,A4) | C4: =COUNTIFS('Test Cases'!$D$2:$D$203,$A4,'Test Cases'!$M$2:$M$203,"Passed") | D4: =COUNTIFS('Test Cases'!$D$2:$D$203,$A4,'Test Cases'!$M$2:$M$203,"Passed (Dev)") | E4: =COUNTIFS('Test Cases'!$D$2:$D$203,$A4,'Test Cases'!$M$2:$M$203,"Failed") | F4: =COUNTIFS('Test Cases'!$D$2:$D$203,$A4,'Test Cases'!$M$2:$M$203,"Blocked") | G4: =COUNTIFS('Test Cases'!$D$2:$D$203,$A4,'Test Cases'!$M$2:$M$203,"Not Run") | H4: =COUNTIFS('Test Cases'!$D$2:$D$203,$A4,'Test Cases'!$M$2:$M$203,"Retired") | I4: =C4+D4+E4 | J4: =IF(I4=0,"-",(C4+D4)/I4)
A5: Listing Purpose | B5: =COUNTIF('Test Cases'!$D$2:$D$203,A5) | C5: =COUNTIFS('Test Cases'!$D$2:$D$203,$A5,'Test Cases'!$M$2:$M$203,"Passed") | D5: =COUNTIFS('Test Cases'!$D$2:$D$203,$A5,'Test Cases'!$M$2:$M$203,"Passed (Dev)") | E5: =COUNTIFS('Test Cases'!$D$2:$D$203,$A5,'Test Cases'!$M$2:$M$203,"Failed") | F5: =COUNTIFS('Test Cases'!$D$2:$D$203,$A5,'Test Cases'!$M$2:$M$203,"Blocked") | G5: =COUNTIFS('Test Cases'!$D$2:$D$203,$A5,'Test Cases'!$M$2:$M$203,"Not Run") | H5: =COUNTIFS('Test Cases'!$D$2:$D$203,$A5,'Test Cases'!$M$2:$M$203,"Retired") | I5: =C5+D5+E5 | J5: =IF(I5=0,"-",(C5+D5)/I5)
A6: Admin Listing Review | B6: =COUNTIF('Test Cases'!$D$2:$D$203,A6) | C6: =COUNTIFS('Test Cases'!$D$2:$D$203,$A6,'Test Cases'!$M$2:$M$203,"Passed") | D6: =COUNTIFS('Test Cases'!$D$2:$D$203,$A6,'Test Cases'!$M$2:$M$203,"Passed (Dev)") | E6: =COUNTIFS('Test Cases'!$D$2:$D$203,$A6,'Test Cases'!$M$2:$M$203,"Failed") | F6: =COUNTIFS('Test Cases'!$D$2:$D$203,$A6,'Test Cases'!$M$2:$M$203,"Blocked") | G6: =COUNTIFS('Test Cases'!$D$2:$D$203,$A6,'Test Cases'!$M$2:$M$203,"Not Run") | H6: =COUNTIFS('Test Cases'!$D$2:$D$203,$A6,'Test Cases'!$M$2:$M$203,"Retired") | I6: =C6+D6+E6 | J6: =IF(I6=0,"-",(C6+D6)/I6)
A7: Private Documents | B7: =COUNTIF('Test Cases'!$D$2:$D$203,A7) | C7: =COUNTIFS('Test Cases'!$D$2:$D$203,$A7,'Test Cases'!$M$2:$M$203,"Passed") | D7: =COUNTIFS('Test Cases'!$D$2:$D$203,$A7,'Test Cases'!$M$2:$M$203,"Passed (Dev)") | E7: =COUNTIFS('Test Cases'!$D$2:$D$203,$A7,'Test Cases'!$M$2:$M$203,"Failed") | F7: =COUNTIFS('Test Cases'!$D$2:$D$203,$A7,'Test Cases'!$M$2:$M$203,"Blocked") | G7: =COUNTIFS('Test Cases'!$D$2:$D$203,$A7,'Test Cases'!$M$2:$M$203,"Not Run") | H7: =COUNTIFS('Test Cases'!$D$2:$D$203,$A7,'Test Cases'!$M$2:$M$203,"Retired") | I7: =C7+D7+E7 | J7: =IF(I7=0,"-",(C7+D7)/I7)
A8: Search & Browse | B8: =COUNTIF('Test Cases'!$D$2:$D$203,A8) | C8: =COUNTIFS('Test Cases'!$D$2:$D$203,$A8,'Test Cases'!$M$2:$M$203,"Passed") | D8: =COUNTIFS('Test Cases'!$D$2:$D$203,$A8,'Test Cases'!$M$2:$M$203,"Passed (Dev)") | E8: =COUNTIFS('Test Cases'!$D$2:$D$203,$A8,'Test Cases'!$M$2:$M$203,"Failed") | F8: =COUNTIFS('Test Cases'!$D$2:$D$203,$A8,'Test Cases'!$M$2:$M$203,"Blocked") | G8: =COUNTIFS('Test Cases'!$D$2:$D$203,$A8,'Test Cases'!$M$2:$M$203,"Not Run") | H8: =COUNTIFS('Test Cases'!$D$2:$D$203,$A8,'Test Cases'!$M$2:$M$203,"Retired") | I8: =C8+D8+E8 | J8: =IF(I8=0,"-",(C8+D8)/I8)
A9: Booking | B9: =COUNTIF('Test Cases'!$D$2:$D$203,A9) | C9: =COUNTIFS('Test Cases'!$D$2:$D$203,$A9,'Test Cases'!$M$2:$M$203,"Passed") | D9: =COUNTIFS('Test Cases'!$D$2:$D$203,$A9,'Test Cases'!$M$2:$M$203,"Passed (Dev)") | E9: =COUNTIFS('Test Cases'!$D$2:$D$203,$A9,'Test Cases'!$M$2:$M$203,"Failed") | F9: =COUNTIFS('Test Cases'!$D$2:$D$203,$A9,'Test Cases'!$M$2:$M$203,"Blocked") | G9: =COUNTIFS('Test Cases'!$D$2:$D$203,$A9,'Test Cases'!$M$2:$M$203,"Not Run") | H9: =COUNTIFS('Test Cases'!$D$2:$D$203,$A9,'Test Cases'!$M$2:$M$203,"Retired") | I9: =C9+D9+E9 | J9: =IF(I9=0,"-",(C9+D9)/I9)
A10: Trusted API | B10: =COUNTIF('Test Cases'!$D$2:$D$203,A10) | C10: =COUNTIFS('Test Cases'!$D$2:$D$203,$A10,'Test Cases'!$M$2:$M$203,"Passed") | D10: =COUNTIFS('Test Cases'!$D$2:$D$203,$A10,'Test Cases'!$M$2:$M$203,"Passed (Dev)") | E10: =COUNTIFS('Test Cases'!$D$2:$D$203,$A10,'Test Cases'!$M$2:$M$203,"Failed") | F10: =COUNTIFS('Test Cases'!$D$2:$D$203,$A10,'Test Cases'!$M$2:$M$203,"Blocked") | G10: =COUNTIFS('Test Cases'!$D$2:$D$203,$A10,'Test Cases'!$M$2:$M$203,"Not Run") | H10: =COUNTIFS('Test Cases'!$D$2:$D$203,$A10,'Test Cases'!$M$2:$M$203,"Retired") | I10: =C10+D10+E10 | J10: =IF(I10=0,"-",(C10+D10)/I10)
A11: Ratings & Completion | B11: =COUNTIF('Test Cases'!$D$2:$D$203,A11) | C11: =COUNTIFS('Test Cases'!$D$2:$D$203,$A11,'Test Cases'!$M$2:$M$203,"Passed") | D11: =COUNTIFS('Test Cases'!$D$2:$D$203,$A11,'Test Cases'!$M$2:$M$203,"Passed (Dev)") | E11: =COUNTIFS('Test Cases'!$D$2:$D$203,$A11,'Test Cases'!$M$2:$M$203,"Failed") | F11: =COUNTIFS('Test Cases'!$D$2:$D$203,$A11,'Test Cases'!$M$2:$M$203,"Blocked") | G11: =COUNTIFS('Test Cases'!$D$2:$D$203,$A11,'Test Cases'!$M$2:$M$203,"Not Run") | H11: =COUNTIFS('Test Cases'!$D$2:$D$203,$A11,'Test Cases'!$M$2:$M$203,"Retired") | I11: =C11+D11+E11 | J11: =IF(I11=0,"-",(C11+D11)/I11)
A12: Disputes | B12: =COUNTIF('Test Cases'!$D$2:$D$203,A12) | C12: =COUNTIFS('Test Cases'!$D$2:$D$203,$A12,'Test Cases'!$M$2:$M$203,"Passed") | D12: =COUNTIFS('Test Cases'!$D$2:$D$203,$A12,'Test Cases'!$M$2:$M$203,"Passed (Dev)") | E12: =COUNTIFS('Test Cases'!$D$2:$D$203,$A12,'Test Cases'!$M$2:$M$203,"Failed") | F12: =COUNTIFS('Test Cases'!$D$2:$D$203,$A12,'Test Cases'!$M$2:$M$203,"Blocked") | G12: =COUNTIFS('Test Cases'!$D$2:$D$203,$A12,'Test Cases'!$M$2:$M$203,"Not Run") | H12: =COUNTIFS('Test Cases'!$D$2:$D$203,$A12,'Test Cases'!$M$2:$M$203,"Retired") | I12: =C12+D12+E12 | J12: =IF(I12=0,"-",(C12+D12)/I12)
A13: Public Profile | B13: =COUNTIF('Test Cases'!$D$2:$D$203,A13) | C13: =COUNTIFS('Test Cases'!$D$2:$D$203,$A13,'Test Cases'!$M$2:$M$203,"Passed") | D13: =COUNTIFS('Test Cases'!$D$2:$D$203,$A13,'Test Cases'!$M$2:$M$203,"Passed (Dev)") | E13: =COUNTIFS('Test Cases'!$D$2:$D$203,$A13,'Test Cases'!$M$2:$M$203,"Failed") | F13: =COUNTIFS('Test Cases'!$D$2:$D$203,$A13,'Test Cases'!$M$2:$M$203,"Blocked") | G13: =COUNTIFS('Test Cases'!$D$2:$D$203,$A13,'Test Cases'!$M$2:$M$203,"Not Run") | H13: =COUNTIFS('Test Cases'!$D$2:$D$203,$A13,'Test Cases'!$M$2:$M$203,"Retired") | I13: =C13+D13+E13 | J13: =IF(I13=0,"-",(C13+D13)/I13)
A14: Trust & Fairness Score | B14: =COUNTIF('Test Cases'!$D$2:$D$203,A14) | C14: =COUNTIFS('Test Cases'!$D$2:$D$203,$A14,'Test Cases'!$M$2:$M$203,"Passed") | D14: =COUNTIFS('Test Cases'!$D$2:$D$203,$A14,'Test Cases'!$M$2:$M$203,"Passed (Dev)") | E14: =COUNTIFS('Test Cases'!$D$2:$D$203,$A14,'Test Cases'!$M$2:$M$203,"Failed") | F14: =COUNTIFS('Test Cases'!$D$2:$D$203,$A14,'Test Cases'!$M$2:$M$203,"Blocked") | G14: =COUNTIFS('Test Cases'!$D$2:$D$203,$A14,'Test Cases'!$M$2:$M$203,"Not Run") | H14: =COUNTIFS('Test Cases'!$D$2:$D$203,$A14,'Test Cases'!$M$2:$M$203,"Retired") | I14: =C14+D14+E14 | J14: =IF(I14=0,"-",(C14+D14)/I14)
... A24: Release & Non-functional | B24: =COUNTIF('Test Cases'!$D$2:$D$203,A24) | C24: =COUNTIFS('Test Cases'!$D$2:$D$203,$A24,'Test Cases'!$M$2:$M$203,"Passed") | D24: =COUNTIFS('Test Cases'!$D$2:$D$203,$A24,'Test Cases'!$M$2:$M$203,"Passed (Dev)") | E24: =COUNTIFS('Test Cases'!$D$2:$D$203,$A24,'Test Cases'!$M$2:$M$203,"Failed") | F24: =COUNTIFS('Test Cases'!$D$2:$D$203,$A24,'Test Cases'!$M$2:$M$203,"Blocked") | G24: =COUNTIFS('Test Cases'!$D$2:$D$203,$A24,'Test Cases'!$M$2:$M$203,"Not Run") | H24: =COUNTIFS('Test Cases'!$D$2:$D$203,$A24,'Test Cases'!$M$2:$M$203,"Retired") | I24: =C24+D24+E24 | J24: =IF(I24=0,"-",(C24+D24)/I24)
A25: TOTAL | B25: =SUM(B3:B24) | C25: =SUM(C3:C24) | D25: =SUM(D3:D24) | E25: =SUM(E3:E24) | F25: =SUM(F3:F24) | G25: =SUM(G3:G24) | H25: =SUM(H3:H24) | I25: =SUM(I3:I24) | J25: =IF(I25=0,"-",(C25+D25)/I25)
A28: By Origin
A29: Existing (QA doc) | B29: =COUNTIF('Test Cases'!$L$2:$L$203,A29)
A30: Updated | B30: =COUNTIF('Test Cases'!$L$2:$L$203,A30)
A31: New | B31: =COUNTIF('Test Cases'!$L$2:$L$203,A31)
A32: Retired | B32: =COUNTIF('Test Cases'!$L$2:$L$203,A32)
A35: Use cases | B35: =COUNTA('Use Cases'!A2:A49)
A36: Unassigned module check (should be 0) | B36: =COUNTA('Test Cases'!A2:A203)-B25
A37: Pass Rate = (Passed + Passed (Dev)) / Executed; Executed = Passed + Passed (Dev) + Failed.

Sheet Proposed FRs
A1: FR ID | B1: Requirement | C1: Priority | D1: Source | E1: Acceptance / Linked Tests
A2: FR-002 (revise) | B2: The system shall require a non-empty description of at most 400 words; 150 words is shown as a recommendation. | C2: HIGH | D2: Progress Report P1 Description | E2: Empty/whitespace rejected; <150 words accepted; >400 rejected.
A3: FR-008 (revise) | B3: Only the renter manually marks a booking Completed; the scheduled job completes expired Confirmed bookings. | C3: MEDIUM | D3: Progress Report P1 Completion | E3: Owner has no completion button; one Completed transition.
A4: FR-009 (revise) | B4: Submitting a dispute sets the booking to Disputed and records its prior status; Dismissed restores it; Founded keeps Disputed. | C4: HIGH | D4: Progress Report P1 Dispute | E4: Booking and dispute states stay consistent; duplicate open disputes blocked.
A5: FR-017 (retire) | B5: Saved Searches removed; /saved-searches redirects to Browse without deleting records. | C5: LOW | D5: Cleanup 2026-09-30 | E5: Redirect works; data preserved.
A6: FR-019 | B6: Only profiles with role admin and status active can render admin routes; missing/unreadable profiles fail closed with retry. | C6: HIGH | D6: Progress Report P0 Admin login | E6: TC-ADM-003 to 008.
A7: FR-020 | B7: Admin notifications are limited to disputes; booking requests notify only the listing owner; feeds are isolated by rules. | C7: HIGH | D7: Progress Report P0 Notifications | E7: TC-NOTIF-005 to 009.
A8: FR-021 | B8: One My Activity page (Listings, Bookings, Requests tabs) and Settings with System/Light/Dark plus persisted accessibility preferences. | C8: LOW | D8: Progress Report P2 Navigation | E8: TC-NAV-001 to 004, TC-SET-001 to 003.
A9: FR-022 | B9: Optional approximate map pin stored as a 5-char geohash; exact address kept in listingPrivate readable by owner/admin only. | C9: MEDIUM | D9: Progress Report P2 Map | E9: TC-MAP-001 to 008, 011, 012.
A10: FR-023 | B10: My Listings shows photo, city, type, bedrooms, price, status, review note and per-listing pending-request counts. | C10: MEDIUM | D10: Progress Report P1 Owner visibility | E10: TC-MYL-001 to 006.
A11: FR-024 | B11: The renter sees the exact property address only after the booking is Confirmed. | C11: HIGH | D11: Build Instructions §2.1; cleanup 2026-09-30 | E11: TC-MAP-009, 010.
A12: FR-025 | B12: Every listing shall declare a purpose (For rent: short-term nightly or long-term monthly; For sale: one-time asking price). Sale listings cannot be booked. | C12: HIGH | D12: Progress Report Oct 1 | E12: TC-PURP-001 to 006.
... A19: NFR-REL-02 | B19: A restorable Firestore backup is taken before every migration or rules change. | C19: HIGH | D19: Infrastructure §8 | E19: TC-OPS-003.
